Workbook

Sheet راهنما
A1: فیچرلیست فریم‌ورک استاندارد تولید استراتژی — نسخهٔ ۱٫۱ (فاز ۳)
A3: ستون | B3: توضیح
A4: شناسه | B4: F-<مرحله>.<بلوک>.<شماره>؛ مبنای تسک‌های Claude Code و ارجاع در کد و تست‌ها. شناسه‌ها هرگز تغییر نمی‌کنند؛ فیچر حذف‌شده وضعیت «لغو» می‌گیرد.
A5: مرحله / ماژول | B5: مرحلهٔ سند مشخصات (نسخهٔ ۱٫۲) و ماژول نرم‌افزاری پیشنهادی.
A6: معیار پذیرش | B6: شرط «انجام‌شده» بودن؛ باید با تست خودکار یا بررسی مشخص قابل راستی‌آزمایی باشد.
A7: اولویت MVP | B7: لازم برای اولین اجرای کامل قیف: مرحلهٔ ۰ + مراحل ۱ تا ۳ + گزارش HTML + خودآزمایی اولیه.
A8: اولویت P1 | B8: لازم برای قیف کامل تا تأیید تحلیلگر (مراحل ۱-S و ۴ تا ۹ و کالیبراسیون).
A9: اولویت P2 | B9: پورتفو، سایزینگ، چرخهٔ عمر و بهبودها.
A10: تسک | B10: شمارهٔ تسک Claude Code طبق سند طراحی بخش ۱۳ (T00 تا T15 برای MVP).
A11: وابستگی‌ها | B11: فیچرهایی که باید پیش از این فیچر تحویل شوند.
A12: وضعیت | B12: برنامه‌ریزی‌شده / در حال انجام / بازبینی / پذیرفته‌شده / لغو — از فهرست کشویی انتخاب شود.
A13: ستون‌های قابل ویرایش | B13: وضعیت و یادداشت (زرد). بقیهٔ ستون‌ها فقط با توافق در چت تغییر می‌کنند.
A14: منبع | B14: همهٔ مقادیر و آستانه‌ها از سند مشخصات نسخهٔ ۱٫۲ و تصمیمات فاز ۱ است.

Sheet خلاصه
A1: مرحله | B1: MVP | C1: P1 | D1: P2 | E1: کل | F1: پذیرفته‌شده | G1: درصد پیشرفت
A2: ۰ زیرساخت | B2: =COUNTIFS(فیچرلیست!$B$2:$B$129,$A2,فیچرلیست!$G$2:$G$129,"MVP") -> 31 | C2: =COUNTIFS(فیچرلیست!$B$2:$B$129,$A2,فیچرلیست!$G$2:$G$129,"P1") -> 9 | D2: =COUNTIFS(فیچرلیست!$B$2:$B$129,$A2,فیچرلیست!$G$2:$G$129,"P2") -> 1 | E2: =SUM(B2:D2) -> 41 | F2: =COUNTIFS(فیچرلیست!$B$2:$B$129,$A2,فیچرلیست!$J$2:$J$129,"پذیرفته‌شده") -> 0 | G2: =IF(E2=0,0,F2/E2) -> 0
A3: ۱ کشف اج | B3: =COUNTIFS(فیچرلیست!$B$2:$B$129,$A3,فیچرلیست!$G$2:$G$129,"MVP") -> 8 | C3: =COUNTIFS(فیچرلیست!$B$2:$B$129,$A3,فیچرلیست!$G$2:$G$129,"P1") -> 1 | D3: =COUNTIFS(فیچرلیست!$B$2:$B$129,$A3,فیچرلیست!$G$2:$G$129,"P2") -> 0 | E3: =SUM(B3:D3) -> 9 | F3: =COUNTIFS(فیچرلیست!$B$2:$B$129,$A3,فیچرلیست!$J$2:$J$129,"پذیرفته‌شده") -> 0 | G3: =IF(E3=0,0,F3/E3) -> 0
A4: ۱-S سیزنال | B4: =COUNTIFS(فیچرلیست!$B$2:$B$129,$A4,فیچرلیست!$G$2:$G$129,"MVP") -> 0 | C4: =COUNTIFS(فیچرلیست!$B$2:$B$129,$A4,فیچرلیست!$G$2:$G$129,"P1") -> 4 | D4: =COUNTIFS(فیچرلیست!$B$2:$B$129,$A4,فیچرلیست!$G$2:$G$129,"P2") -> 0 | E4: =SUM(B4:D4) -> 4 | F4: =COUNTIFS(فیچرلیست!$B$2:$B$129,$A4,فیچرلیست!$J$2:$J$129,"پذیرفته‌شده") -> 0 | G4: =IF(E4=0,0,F4/E4) -> 0
A5: ۲ غربال متد | B5: =COUNTIFS(فیچرلیست!$B$2:$B$129,$A5,فیچرلیست!$G$2:$G$129,"MVP") -> 7 | C5: =COUNTIFS(فیچرلیست!$B$2:$B$129,$A5,فیچرلیست!$G$2:$G$129,"P1") -> 0 | D5: =COUNTIFS(فیچرلیست!$B$2:$B$129,$A5,فیچرلیست!$G$2:$G$129,"P2") -> 0 | E5: =SUM(B5:D5) -> 7 | F5: =COUNTIFS(فیچرلیست!$B$2:$B$129,$A5,فیچرلیست!$J$2:$J$129,"پذیرفته‌شده") -> 0 | G5: =IF(E5=0,0,F5/E5) -> 0
A6: ۳ بهینه‌سازی ورود | B6: =COUNTIFS(فیچرلیست!$B$2:$B$129,$A6,فیچرلیست!$G$2:$G$129,"MVP") -> 6 | C6: =COUNTIFS(فیچرلیست!$B$2:$B$129,$A6,فیچرلیست!$G$2:$G$129,"P1") -> 1 | D6: =COUNTIFS(فیچرلیست!$B$2:$B$129,$A6,فیچرلیست!$G$2:$G$129,"P2") -> 0 | E6: =SUM(B6:D6) -> 7 | F6: =COUNTIFS(فیچرلیست!$B$2:$B$129,$A6,فیچرلیست!$J$2:$J$129,"پذیرفته‌شده") -> 0 | G6: =IF(E6=0,0,F6/E6) -> 0
A7: ۴ خروج | B7: =COUNTIFS(فیچرلیست!$B$2:$B$129,$A7,فیچرلیست!$G$2:$G$129,"MVP") -> 0 | C7: =COUNTIFS(فیچرلیست!$B$2:$B$129,$A7,فیچرلیست!$G$2:$G$129,"P1") -> 5 | D7: =COUNTIFS(فیچرلیست!$B$2:$B$129,$A7,فیچرلیست!$G$2:$G$129,"P2") -> 0 | E7: =SUM(B7:D7) -> 5 | F7: =COUNTIFS(فیچرلیست!$B$2:$B$129,$A7,فیچرلیست!$J$2:$J$129,"پذیرفته‌شده") -> 0 | G7: =IF(E7=0,0,F7/E7) -> 0
A8: ۵ تشخیص و فیلتر | B8: =COUNTIFS(فیچرلیست!$B$2:$B$129,$A8,فیچرلیست!$G$2:$G$129,"MVP") -> 0 | C8: =COUNTIFS(فیچرلیست!$B$2:$B$129,$A8,فیچرلیست!$G$2:$G$129,"P1") -> 6 | D8: =COUNTIFS(فیچرلیست!$B$2:$B$129,$A8,فیچرلیست!$G$2:$G$129,"P2") -> 1 | E8: =SUM(B8:D8) -> 7 | F8: =COUNTIFS(فیچرلیست!$B$2:$B$129,$A8,فیچرلیست!$J$2:$J$129,"پذیرفته‌شده") -> 0 | G8: =IF(E8=0,0,F8/E8) -> 0
A9: ۶ روباستنس | B9: =COUNTIFS(فیچرلیست!$B$2:$B$129,$A9,فیچرلیست!$G$2:$G$129,"MVP") -> 0 | C9: =COUNTIFS(فیچرلیست!$B$2:$B$129,$A9,فیچرلیست!$G$2:$G$129,"P1") -> 9 | D9: =COUNTIFS(فیچرلیست!$B$2:$B$129,$A9,فیچرلیست!$G$2:$G$129,"P2") -> 0 | E9: =SUM(B9:D9) -> 9 | F9: =COUNTIFS(فیچرلیست!$B$2:$B$129,$A9,فیچرلیست!$J$2:$J$129,"پذیرفته‌شده") -> 0 | G9: =IF(E9=0,0,F9/E9) -> 0
A10: ۷ آماری | B10: =COUNTIFS(فیچرلیست!$B$2:$B$129,$A10,فیچرلیست!$G$2:$G$129,"MVP") -> 0 | C10: =COUNTIFS(فیچرلیست!$B$2:$B$129,$A10,فیچرلیست!$G$2:$G$129,"P1") -> 6 | D10: =COUNTIFS(فیچرلیست!$B$2:$B$129,$A10,فیچرلیست!$G$2:$G$129,"P2") -> 1 | E10: =SUM(B10:D10) -> 7 | F10: =COUNTIFS(فیچرلیست!$B$2:$B$129,$A10,فیچرلیست!$J$2:$J$129,"پذیرفته‌شده") -> 0 | G10: =IF(E10=0,0,F10/E10) -> 0
A11: ۸ گزارش LLM | B11: =COUNTIFS(فیچرلیست!$B$2:$B$129,$A11,فیچرلیست!$G$2:$G$129,"MVP") -> 0 | C11: =COUNTIFS(فیچرلیست!$B$2:$B$129,$A11,فیچرلیست!$G$2:$G$129,"P1") -> 5 | D11: =COUNTIFS(فیچرلیست!$B$2:$B$129,$A11,فیچرلیست!$G$2:$G$129,"P2") -> 1 | E11: =SUM(B11:D11) -> 6 | F11: =COUNTIFS(فیچرلیست!$B$2:$B$129,$A11,فیچرلیست!$J$2:$J$129,"پذیرفته‌شده") -> 0 | G11: =IF(E11=0,0,F11/E11) -> 0
A12: ۹ تحلیلگر | B12: =COUNTIFS(فیچرلیست!$B$2:$B$129,$A12,فیچرلیست!$G$2:$G$129,"MVP") -> 0 | C12: =COUNTIFS(فیچرلیست!$B$2:$B$129,$A12,فیچرلیست!$G$2:$G$129,"P1") -> 2 | D12: =COUNTIFS(فیچرلیست!$B$2:$B$129,$A12,فیچرلیست!$G$2:$G$129,"P2") -> 0 | E12: =SUM(B12:D12) -> 2 | F12: =COUNTIFS(فیچرلیست!$B$2:$B$129,$A12,فیچرلیست!$J$2:$J$129,"پذیرفته‌شده") -> 0 | G12: =IF(E12=0,0,F12/E12) -> 0
A13: ۱۰ پورتفو | B13: =COUNTIFS(فیچرلیست!$B$2:$B$129,$A13,فیچرلیست!$G$2:$G$129,"MVP") -> 0 | C13: =COUNTIFS(فیچرلیست!$B$2:$B$129,$A13,فیچرلیست!$G$2:$G$129,"P1") -> 0 | D13: =COUNTIFS(فیچرلیست!$B$2:$B$129,$A13,فیچرلیست!$G$2:$G$129,"P2") -> 4 | E13: =SUM(B13:D13) -> 4 | F13: =COUNTIFS(فیچرلیست!$B$2:$B$129,$A13,فیچرلیست!$J$2:$J$129,"پذیرفته‌شده") -> 0 | G13: =IF(E13=0,0,F13/E13) -> 0
... A16: مشترک | B16: =COUNTIFS(فیچرلیست!$B$2:$B$129,$A16,فیچرلیست!$G$2:$G$129,"MVP") -> 8 | C16: =COUNTIFS(فیچرلیست!$B$2:$B$129,$A16,فیچرلیست!$G$2:$G$129,"P1") -> 2 | D16: =COUNTIFS(فیچرلیست!$B$2:$B$129,$A16,فیچرلیست!$G$2:$G$129,"P2") -> 0 | E16: =SUM(B16:D16) -> 10 | F16: =COUNTIFS(فیچرلیست!$B$2:$B$129,$A16,فیچرلیست!$J$2:$J$129,"پذیرفته‌شده") -> 0 | G16: =IF(E16=0,0,F16/E16) -> 0
A17: جمع کل | B17: =SUM(B2:B16) -> 60 | C17: =SUM(C2:C16) -> 50 | D17: =SUM(D2:D16) -> 18 | E17: =SUM(E2:E16) -> 128 | F17: =SUM(F2:F16) -> 0 | G17: =IF(E17=0,0,F17/E17) -> 0

Sheet فیچرلیست
A1: شناسه | B1: مرحله | C1: ماژول | D1: عنوان | E1: شرح | F1: معیار پذیرش | G1: اولویت | H1: تسک | I1: وابستگی‌ها | J1: وضعیت | K1: یادداشت
A2: F-0.1.1 | B2: ۰ زیرساخت | C2: data | D2: فرمت استاندارد و رابط آداپتور | E2: تعریف اسکیما واحد: ts (شروع بار، UTC)، open/high/low/close/volume و ستون‌های اختیاری vwap، trades، spread؛ به‌همراه متادیتای سری: منبع، نماد منبع، نماد استاندارد، کلاس دارایی، تایم‌فریم، نوع قیمت، تعدیل، سشن، فید، منطقهٔ زمانی اصلی، تاریخ دانلود. | F2: هر آداپتور خروجی معتبر طبق اسکیما می‌دهد؛ اعتبارسنج اسکیما روی ستون یا متادیتای ناقص خطا می‌دهد؛ تست واحد برای هر فیلد. | G2: MVP | H2: T02 | J2: برنامه‌ریزی‌شده
A3: F-0.1.2 | B3: ۰ زیرساخت | C3: data | D3: آداپتور Alpaca | E3: خواندن فایل‌های Alpaca (سهام آمریکا)، تبدیل به UTC، فیلتر سشن رسمی (RTH) با گزینهٔ نگه‌داشتن ETH، ثبت فید (IEX/SIP) و نوع تعدیل در متادیتا. | F3: روی نمونهٔ واقعی فایل‌ها بدون خطا اجرا می‌شود؛ بارهای خارج از سشن رسمی در حالت RTH حذف می‌شوند؛ فید و تعدیل در متادیتا ثبت است. (جزئیات فرمت پس از دریافت نمونه‌فایل) | G3: MVP | H3: T04 | I3: F-0.1.1 | J3: برنامه‌ریزی‌شده
A4: F-0.1.3 | B4: ۰ زیرساخت | C4: data | D4: آداپتور Dukascopy | E4: خواندن CSV با تایم‌استمپ میلی‌ثانیه‌ای، اصلاح آفست UTC، تبدیل واحد حجم، ادغام سری bid و ask و ساخت mid و spread. | F4: سری bid و ask روی تایم‌استمپ یکسان هم‌تراز می‌شوند؛ spread = ask − bid همیشه نامنفی؛ آفست UTC هنگام دانلود از کانفیگ خوانده و اصلاح می‌شود. | G4: MVP | H4: T04 | I4: F-0.1.1 | J4: برنامه‌ریزی‌شده
A5: F-0.1.4 | B5: ۰ زیرساخت | C5: data | D5: آداپتور Yahoo | E5: خواندن دادهٔ روزانه و سری‌های کمکی (VIX، شاخص‌ها)، ثبت وضعیت auto_adjust و منطقهٔ زمانی. | F5: دادهٔ روزانه با تاریخ درست و متادیتای تعدیل ثبت می‌شود؛ سری کمکی قابل استفاده در F-0.1.11 است. | G5: P1 | H5: — | I5: F-0.1.1 | J5: برنامه‌ریزی‌شده
A6: F-0.1.5 | B6: ۰ زیرساخت | C6: data | D6: آداپتور خروجی TradingView | E6: خواندن OHLC و فهرست تریدهای خروجی TradingView برای تست تطابق. | F6: فهرست تریدها (زمان و قیمت ورود و خروج، جهت، سود) به ساختار استاندارد ترید تبدیل می‌شود. | G6: MVP | H6: T04 | I6: F-0.1.1 | J6: برنامه‌ریزی‌شده
A7: F-0.1.6 | B7: ۰ زیرساخت | C7: data | D7: بررسی کیفیت داده و گزارش | E7: تشخیص کندل گمشده، تکراری، جهش قیمت غیرعادی، High کمتر از Low، حجم صفر، ناپیوستگی DST؛ سطح‌بندی شدت (بحرانی/هشدار/اطلاع). | F7: روی دادهٔ آلوده‌شدهٔ ساختگی همهٔ انواع خطا کشف می‌شوند؛ گزارش کیفیت برای هر نماد تولید می‌شود؛ خطای بحرانی اجرای قیف را متوقف می‌کند. | G7: MVP | H7: T05 | I7: F-0.1.1 | J7: برنامه‌ریزی‌شده
A8: F-0.1.7 | B8: ۰ زیرساخت | C8: data | D8: بازنمونه‌گیری و مرز روز | E8: ساخت تایم‌فریم‌های بالاتر از پایین‌تر؛ مرز روز ۰۰:۰۰ UTC؛ ادغام ساعات یکشنبهٔ فارکس و طلا در دوشنبه؛ حالت «مرز سشن بروکر» برای تست تطابق. | F8: مجموع حجم و OHLC بازنمونه‌شده با محاسبهٔ دستی برابر است؛ هیچ کندل روزانهٔ یکشنبه در فارکس و طلا وجود ندارد؛ حالت بروکر با کندل‌های TradingView منطبق است. | G8: MVP | H8: T05 | I8: F-0.1.1 | J8: برنامه‌ریزی‌شده
A9: F-0.1.8 | B9: ۰ زیرساخت | C9: data | D9: ذخیره‌سازی و نسخه‌بندی داده | E9: ذخیرهٔ اسنپ‌شات‌های تغییرناپذیر با شناسه و هش؛ هر نتیجه به نسخهٔ داده ارجاع می‌دهد. | F9: بازنویسی یک اسنپ‌شات موجود ممکن نیست؛ تغییر یک مقدار، هش جدید می‌سازد. | G9: MVP | H9: T02 | I9: F-0.1.1 | J9: برنامه‌ریزی‌شده
A10: F-0.1.9 | B10: ۰ زیرساخت | C10: data | D10: کنترل تعدیل سهام | E10: بررسی سازگاری تعدیل اسپلیت و سود تقسیمی بین منابع و در طول زمان. | F10: جهش‌های ناشی از اسپلیت تعدیل‌نشده تشخیص و گزارش می‌شوند. | G10: P1 | H10: — | I10: F-0.1.2 | J10: برنامه‌ریزی‌شده
A11: F-0.1.10 | B11: ۰ زیرساخت | C11: data | D11: رول‌اور قراردادهای آتی | E11: ساخت سری پیوسته برای قراردادهای آتی (در صورت اضافه شدن این کلاس دارایی). | F11: سری پیوسته بدون گپ مصنوعی رول‌اور ساخته می‌شود. | G11: P2 | H11: — | I11: F-0.1.1 | J11: برنامه‌ریزی‌شده
A12: F-0.1.11 | B12: ۰ زیرساخت | C12: data | D12: هم‌ترازی سری‌های کمکی | E12: اتصال سری‌های کمکی (VIX، شاخص مرجع) به نماد به‌صورت as-of با تأخیر، طوری که فقط مقدار بسته‌شدهٔ قبلی در دسترس باشد. | F12: تست نشت: هیچ کندلی به مقدار سری کمکی هم‌زمان یا آینده دسترسی ندارد. | G12: P1 | H12: — | I12: F-0.1.4 | J12: برنامه‌ریزی‌شده
A13: F-0.1.12 | B13: ۰ زیرساخت | C13: data | D13: فهرست دارایی داده (Data inventory) | E13: بررسی فقط‌خواندنی پوشه‌های دادهٔ موجود: منبع، کلاس دارایی، نمادها، تایم‌فریم، بازه، فرمت، ستون‌ها، منطقهٔ زمانی، نوع قیمت، نشانه‌های تعدیل و سشن؛ خروجی docs/data_inventory.md و json. | F13: همهٔ گروه‌های فایل با نمونهٔ سطرها و شواهد مستند شده‌اند؛ هیچ فایلی تغییر نکرده؛ فهرست پرسش‌های باز برای کاربر. | G13: MVP | H13: T00 | J13: برنامه‌ریزی‌شده
A14: F-0.2.1 | B14: ۰ زیرساخت | C14: costs | D14: اسکیما پروفایل هزینه | E14: پروفایل برای هر نماد و بروکر: اسپرد، مدل کمیسیون (درصدی/سهمی/لاتی)، سواپ لانگ و شورت، روز سه‌برابر، مدل اسلیپیج (ثابت + کسری از ATR). | F14: پروفایل از کانفیگ خوانده و اعتبارسنجی می‌شود؛ نبود پروفایل برای یک نماد خطا می‌دهد (هزینه اختیاری نیست). | G14: MVP | H14: T06 | J14: برنامه‌ریزی‌شده
A15: F-0.2.2 | B15: ۰ زیرساخت | C15: costs | D15: پروفایل ساعتی اسپرد | E15: ساخت اسپرد به تفکیک ساعت روز از bid و ask دیوکاسکپی و مقیاس‌دهی با اسپرد میانگین بروکر اجرا. | F15: پروفایل ۲۴ ساعته برای هر نماد تولید می‌شود؛ میانگین وزنی پس از مقیاس‌دهی برابر اسپرد بروکر است. | G15: P1 | H15: — | I15: F-0.1.3, F-0.2.1 | J15: برنامه‌ریزی‌شده
A16: F-0.2.3 | B16: ۰ زیرساخت | C16: costs | D16: محاسبهٔ سواپ | E16: اعمال سواپ روزانه برای پوزیشن‌های شبانه با روز سه‌برابر مطابق پروفایل. | F16: روی سناریوی ساختگی، سواپ محاسبه‌شده با محاسبهٔ دستی برابر است. | G16: MVP | H16: T06 | I16: F-0.2.1 | J16: برنامه‌ریزی‌شده
A17: F-0.2.4 | B17: ۰ زیرساخت | C17: costs | D17: ضرایب استرس هزینه | E17: اجرای دوباره با ضرایب ۱٫۵، ۲ و ۳ روی اسپرد و اسلیپیج. | F17: نتایج استرس در کنار نتیجهٔ عادی ذخیره می‌شوند؛ سود با افزایش ضریب به‌طور یکنوا کاهش می‌یابد. | G17: MVP | H17: T06 | I17: F-0.2.1 | J17: برنامه‌ریزی‌شده
A18: F-0.3.1 | B18: ۰ زیرساخت | C18: engine | D18: هستهٔ موتور بک‌تست | E18: سیگنال روی کلوز، اجرا در اوپن کندل بعد؛ لانگ و شورت جدا؛ سرمایهٔ ۱۰۰ هزار و حجم ثابت ۱۰۰ هزار دلار؛ اکوئیتی Mark-to-Market روی کلوز هر کندل؛ خروجی فهرست ترید و منحنی اکوئیتی. | F18: روی استراتژی‌های ساختگی با نتیجهٔ معلوم، تریدها و اکوئیتی دقیقاً با محاسبهٔ دستی برابرند. | G18: MVP | H18: T08 | I18: F-0.1.1, F-0.2.1 | J18: برنامه‌ریزی‌شده
A19: F-0.3.2 | B19: ۰ زیرساخت | C19: engine | D19: خروج‌های پایه | E19: خروج زمانی (N کندل)، خروج سیگنالی، استاپ فاجعهٔ ثابت ۳ATR، ترکیب «اولین رخداد». | F19: هر نوع خروج در تست واحد با سناریوی معلوم در کندل درست و با قیمت درست بسته می‌شود. | G19: MVP | H19: T08 | I19: F-0.3.1 | J19: برنامه‌ریزی‌شده
A20: F-0.3.3 | B20: ۰ زیرساخت | C20: engine | D20: خروج‌های پیشرفته | E20: TP و SL بر حسب ATR، تریلینگ ATR، شاندلیه، بریک‌ایون. | F20: مانند F-0.3.2 برای هر نوع خروج. | G20: P1 | H20: — | I20: F-0.3.2 | J20: برنامه‌ریزی‌شده
A21: F-0.3.4 | B21: ۰ زیرساخت | C21: engine | D21: ابهام درون‌کندلی: حالت تطابق و بدبینانه | E21: حالت «تطابق» با منطق TradingView و حالت «تحقیق» با فرض بدبینانه (حد ضرر اول). | F21: در کندلی که SL و TP هر دو لمس شده‌اند، هر حالت نتیجهٔ مورد انتظار خود را می‌دهد. | G21: MVP | H21: T08 | I21: F-0.3.1 | J21: برنامه‌ریزی‌شده
A22: F-0.3.5 | B22: ۰ زیرساخت | C22: engine | D22: ابهام درون‌کندلی: حل با دادهٔ دقیقه‌ای | E22: در حالت تحقیق، اگر دادهٔ دقیقه‌ای موجود است، ترتیب واقعی لمس SL/TP از آن تعیین شود. | F22: روی نمونهٔ واقعی، ترتیب با بررسی دستی دادهٔ دقیقه‌ای منطبق است. | G22: P1 | H22: — | I22: F-0.3.4 | J22: برنامه‌ریزی‌شده
A23: F-0.3.6 | B23: ۰ زیرساخت | C23: engine | D23: چند استراتژی هم‌زمان روی یک نماد | E23: اجرای موازی چند استراتژی مستقل روی یک نماد با اکوئیتی ترکیبی. | F23: اکوئیتی ترکیبی برابر مجموع اکوئیتی‌های مستقل است. | G23: P1 | H23: — | I23: F-0.3.1 | J23: برنامه‌ریزی‌شده
A24: F-0.3.7 | B24: ۰ زیرساخت | C24: engine | D24: اجرای دسته‌ای و موازی | E24: اجرای گرید و شبیه‌سازی‌ها به‌صورت موازی با ثبت در رجیستری. | F24: نتیجهٔ اجرای موازی با اجرای ترتیبی یکسان است؛ مقیاس‌پذیری با تعداد هسته اندازه‌گیری و گزارش می‌شود. | G24: MVP | H24: T10 | I24: F-0.3.1, F-0.7.1 | J24: برنامه‌ریزی‌شده
A25: F-0.3.8 | B25: ۰ زیرساخت | C25: engine | D25: تست تطابق (Parity) با TradingView | E25: مقایسهٔ ترید به ترید با خروجی TradingView برای دو استراتژی مرجع (MR روزانهٔ SPX500 و TF یک‌ساعته). | F25: حداقل ۹۸٪ تریدها منطبق؛ اختلاف سود خالص حداکثر ۳٪؛ گزارش اختلاف‌ها با دلیل. | G25: MVP | H25: T11 | I25: F-0.1.5, F-0.3.4, F-0.1.7 | J25: برنامه‌ریزی‌شده
A26: F-0.3.9 | B26: ۰ زیرساخت | C26: engine | D26: تست‌های نشت اطلاعات (Look-ahead) | E26: مجموعه تست که بررسی می‌کند هیچ سیگنال یا اندیکاتوری از دادهٔ آینده استفاده نمی‌کند. | F26: تست «برش داده»: نتیجهٔ سیگنال تا کندل t با حذف داده‌های بعد از t تغییر نمی‌کند. | G26: MVP | H26: T08 | I26: F-0.3.1, F-0.4.2 | J26: برنامه‌ریزی‌شده
A27: F-0.4.1 | B27: ۰ زیرساخت | C27: components | D27: رابط اجزای استراتژی | E27: ورود، خروج، فیلتر و سایزینگ به‌صورت اجزای مستقل؛ هر جزء پارامترهایش را اعلام می‌کند (نام، بازه، ۴ مقدار گرید درشت، گام گرید ریز، پیش‌فرض). | F27: افزودن یک متد جدید فقط با ثبت یک کلاس/تابع جدید ممکن است، بدون تغییر کد مراحل. | G27: MVP | H27: T07 | J27: برنامه‌ریزی‌شده
A28: F-0.4.2 | B28: ۰ زیرساخت | C28: components | D28: کتابخانهٔ اندیکاتورها | E28: ATR، انواع MA، RSI، IBS، بولینجر، دانچین، سوپرترند، ایچیموکو، MACD، ROC، Z-Score و سایر موارد مورد نیاز مراحل ۱ و ۲. | F28: مقادیر هر اندیکاتور با مرجع (TradingView یا کتابخانهٔ مرجع) در تلورانس تعریف‌شده برابر است. | G28: MVP | H28: T07 | I28: F-0.4.1 | J28: برنامه‌ریزی‌شده
A29: F-0.4.3 | B29: ۰ زیرساخت | C29: components | D29: برچسب نوع اج و جهت | E29: هر متد برچسب MR/TF/سیزنال و جهت‌های مجاز دارد؛ نسخهٔ شورت آینهٔ لانگ است. | F29: مراحل فقط متدهای مرتبط با نوع اج را انتخاب می‌کنند؛ تست آینه برای شورت. | G29: MVP | H29: T07 | I29: F-0.4.1 | J29: برنامه‌ریزی‌شده
A30: F-0.5.1 | B30: ۰ زیرساخت | C30: metrics | D30: متریک‌های استاندارد تیم | E30: میانگین سود سالانه (سال‌های ناقص کسری)، دراودان سالانه در دو نسخه (از اول سال — مبنا؛ و نسبت به قلهٔ کل)، نسبت سود به دراودان، اکسپوژر، بازده به ازای اکسپوژر، PF، وین‌ریت، امید ریاضی (دلار، درصد، ATR)، تعداد ترید، میانگین مدت نگهداری. | F30: روی اکوئیتی ساختگی با پاسخ معلوم، همهٔ متریک‌ها درست‌اند؛ دراودان نسبت به سرمایهٔ اولیه محاسبه می‌شود. | G30: MVP | H30: T09 | I30: F-0.3.1 | J30: برنامه‌ریزی‌شده
A31: F-0.5.2 | B31: ۰ زیرساخت | C31: metrics | D31: متریک‌های ریسک و توزیع | E31: شارپ و سورتینو روزانه، بیشینهٔ دراودان، Ulcer Index، زمان زیر آب، چولگی و کشیدگی بازده تریدها. | F31: مقادیر با پیاده‌سازی مرجع برابرند. | G31: MVP | H31: T09 | I31: F-0.5.1 | J31: برنامه‌ریزی‌شده
A32: F-0.5.3 | B32: ۰ زیرساخت | C32: metrics | D32: MAE، MFE و Edge Ratio | E32: محاسبهٔ حرکت نامطلوب و مطلوب هر ترید و Edge Ratio برای ۱ تا N کندل پس از ورود. | F32: روی تریدهای ساختگی مقادیر درست‌اند. | G32: P1 | H32: — | I32: F-0.3.1 | J32: برنامه‌ریزی‌شده
A33: F-0.5.4 | B33: ۰ زیرساخت | C33: metrics | D33: متریک‌های سالانه و ماهانه | E33: جدول متریک‌ها به تفکیک سال و ماه برای گزارش و تست یکنواختی. | F33: جمع سود ماهانه برابر سود سالانه و کل است. | G33: MVP | H33: T09 | I33: F-0.5.1 | J33: برنامه‌ریزی‌شده
A34: F-0.6.1 | B34: ۰ زیرساخت | C34: data | D34: مدیر تقسیم داده و قفل هولدآوت | E34: تقسیم توسعه / Embargo / هولدآوت (۲۰٪ انتهایی، حداقل ۱۸ ماه)؛ طول Embargo = بلندترین lookback + بیشینهٔ مدت نگهداری؛ دسترسی به هولدآوت فقط از مرحلهٔ ۶ و یک بار، با ثبت در رجیستری؛ هشدار اگر ترید مورد انتظار در هولدآوت کمتر از ۳۰ باشد. | F34: هر تلاش برای خواندن هولدآوت خارج از مرحلهٔ ۶ خطا می‌دهد؛ دسترسی دوم به هولدآوت مصرف‌شده مسدود است. | G34: MVP | H34: T05 | I34: F-0.1.8, F-0.7.1 | J34: برنامه‌ریزی‌شده
A35: F-0.7.1 | B35: ۰ زیرساخت | C35: registry | D35: رجیستری تریال‌ها | E35: ثبت هر اجرا: شناسه، مرحله، نماد، تایم‌فریم، جهت، استراتژی، پارامترها، هش کانفیگ، نسخهٔ داده، نسخهٔ کد، seed، متریک‌ها، زمان. شبیه‌سازی‌های MC و بوت‌استرپ تریال نیستند و فقط خلاصهٔ توزیع ذخیره می‌شود. | F35: همهٔ اجراهای یک قیف قابل پرس‌وجو هستند؛ تعداد تریال‌ها با تعداد پیکربندی‌های ارزیابی‌شده برابر است. | G35: MVP | H35: T03 | J35: برنامه‌ریزی‌شده
A36: F-0.7.2 | B36: ۰ زیرساخت | C36: registry | D36: شمارش تریال به تفکیک خانوادهٔ جستجو | E36: نگه‌داری تعداد خام تریال‌ها برای هر کاندید در کل مسیر قیف. | F36: برای هر کاندید، تعداد تریال همهٔ مراحل قبلی قابل استخراج است. | G36: MVP | H36: T03 | I36: F-0.7.1 | J36: برنامه‌ریزی‌شده
A37: F-0.7.3 | B37: ۰ زیرساخت | C37: registry | D37: ثبت گیت‌ها، هولدآوت و تصمیمات | E37: ثبت نتیجهٔ هر معیار گیت (مقدار، آستانه، عبور/رد، دلیل)، مصرف هولدآوت، تصمیم تحلیلگر. | F37: مسیر کامل هر کاندید در قیف از رجیستری بازسازی می‌شود. | G37: MVP | H37: T03 | I37: F-0.7.1 | J37: برنامه‌ریزی‌شده
A38: F-0.7.4 | B38: ۰ زیرساخت | C38: registry | D38: بازتولید اجرا | E38: اجرای دوبارهٔ هر تریال از روی شناسهٔ رجیستری. | F38: نتیجهٔ بازتولید بیت‌به‌بیت با نتیجهٔ اصلی یکسان است. | G38: MVP | H38: T03 | I38: F-0.7.1, F-0.1.8 | J38: برنامه‌ریزی‌شده
A39: F-0.8.1 | B39: ۰ زیرساخت | C39: gates | D39: موتور گیت اعلامی | E39: تعریف گیت‌ها در کانفیگ (متریک، عملگر، آستانه) با امکان بازنویسی برای هر کلاس دارایی و تایم‌فریم؛ هیچ آستانه‌ای در کد نیست. | F39: تغییر آستانه در کانفیگ بدون تغییر کد، نتیجهٔ گیت را تغییر می‌دهد؛ هر نتیجه با دلیل ثبت می‌شود. | G39: MVP | H39: T10 | I39: F-0.7.3 | J39: برنامه‌ریزی‌شده
A40: F-0.8.2 | B40: ۰ زیرساخت | C40: gates | D40: کانفیگ اجرای قیف | E40: یک فایل کانفیگ برای اجرای قیف یک نماد یا یونیورس، با هش. | F40: اجرای دوباره با همان کانفیگ و نسخهٔ داده نتیجهٔ یکسان می‌دهد. | G40: MVP | H40: T10 | J40: برنامه‌ریزی‌شده
...
